Workbook

Sheet Summary
A1: NTD after PO — test execution summary
A2: PR #5880 · Procol-Tech/procol-client-dashboard · feat/ntd-after-po → main
A3: https://github.com/Procol-Tech/procol-client-dashboard/pull/5880
A5: How to use this sheet
A6: Fill in the light-yellow columns on the Test Cases tab (Status → Build / Env). Everything on this tab updates from them.
A7: Status is a dropdown: Not Run, Pass, Fail, Blocked, N/A. Put the ticket number in Bug / Ticket whenever Status is Fail.
A8: Example of a filled row: Status = Fail · Actual Result = "Approval sidebar shows all lots, not Lot 2" · Bug / Ticket = PROC-1234 · Tested By = Animesh · Tested On = 24-Sep-2026 · Build / Env = QA, v9.4.418
A9: Flag = "Suspected bug" means the code reading already points to a defect. "Needs product call" means expected behaviour must be agreed first (see Open Questions).
A10: Quick smoke order: 001 → 005 → 015 → 016 → 029 → 031 → 042 → 050 → 051 → 057 → 061, then 017 → 060 (NTD off) and 023 on a lot-based tenant.
A11: By module
A12: Module | B12: Total | C12: Pass | D12: Fail | E12: Blocked | F12: N/A | G12: Not Run | H12: Pass %
A13: Getting to the PO form | B13: =COUNTIFS('Test Cases'!$B$2:$B$67,$A13) | C13: =COUNTIFS('Test Cases'!$B$2:$B$67,$A13,'Test Cases'!$K$2:$K$67,"Pass") | D13: =COUNTIFS('Test Cases'!$B$2:$B$67,$A13,'Test Cases'!$K$2:$K$67,"Fail") | E13: =COUNTIFS('Test Cases'!$B$2:$B$67,$A13,'Test Cases'!$K$2:$K$67,"Blocked") | F13: =COUNTIFS('Test Cases'!$B$2:$B$67,$A13,'Test Cases'!$K$2:$K$67,"N/A") | G13: =COUNTIFS('Test Cases'!$B$2:$B$67,$A13,'Test Cases'!$K$2:$K$67,"Not Run") | H13: =IFERROR(C13/(B13-F13-G13),0)
A14: The PO form — fields and validation | B14: =COUNTIFS('Test Cases'!$B$2:$B$67,$A14) | C14: =COUNTIFS('Test Cases'!$B$2:$B$67,$A14,'Test Cases'!$K$2:$K$67,"Pass") | D14: =COUNTIFS('Test Cases'!$B$2:$B$67,$A14,'Test Cases'!$K$2:$K$67,"Fail") | E14: =COUNTIFS('Test Cases'!$B$2:$B$67,$A14,'Test Cases'!$K$2:$K$67,"Blocked") | F14: =COUNTIFS('Test Cases'!$B$2:$B$67,$A14,'Test Cases'!$K$2:$K$67,"N/A") | G14: =COUNTIFS('Test Cases'!$B$2:$B$67,$A14,'Test Cases'!$K$2:$K$67,"Not Run") | H14: =IFERROR(C14/(B14-F14-G14),0)
A15: "Submit Proposal" on the PO form — the core change | B15: =COUNTIFS('Test Cases'!$B$2:$B$67,$A15) | C15: =COUNTIFS('Test Cases'!$B$2:$B$67,$A15,'Test Cases'!$K$2:$K$67,"Pass") | D15: =COUNTIFS('Test Cases'!$B$2:$B$67,$A15,'Test Cases'!$K$2:$K$67,"Fail") | E15: =COUNTIFS('Test Cases'!$B$2:$B$67,$A15,'Test Cases'!$K$2:$K$67,"Blocked") | F15: =COUNTIFS('Test Cases'!$B$2:$B$67,$A15,'Test Cases'!$K$2:$K$67,"N/A") | G15: =COUNTIFS('Test Cases'!$B$2:$B$67,$A15,'Test Cases'!$K$2:$K$67,"Not Run") | H15: =IFERROR(C15/(B15-F15-G15),0)
A16: The NTD (entity) form | B16: =COUNTIFS('Test Cases'!$B$2:$B$67,$A16) | C16: =COUNTIFS('Test Cases'!$B$2:$B$67,$A16,'Test Cases'!$K$2:$K$67,"Pass") | D16: =COUNTIFS('Test Cases'!$B$2:$B$67,$A16,'Test Cases'!$K$2:$K$67,"Fail") | E16: =COUNTIFS('Test Cases'!$B$2:$B$67,$A16,'Test Cases'!$K$2:$K$67,"Blocked") | F16: =COUNTIFS('Test Cases'!$B$2:$B$67,$A16,'Test Cases'!$K$2:$K$67,"N/A") | G16: =COUNTIFS('Test Cases'!$B$2:$B$67,$A16,'Test Cases'!$K$2:$K$67,"Not Run") | H16: =IFERROR(C16/(B16-F16-G16),0)
A17: "Submit Proposal" on the NTD form — the core change | B17: =COUNTIFS('Test Cases'!$B$2:$B$67,$A17) | C17: =COUNTIFS('Test Cases'!$B$2:$B$67,$A17,'Test Cases'!$K$2:$K$67,"Pass") | D17: =COUNTIFS('Test Cases'!$B$2:$B$67,$A17,'Test Cases'!$K$2:$K$67,"Fail") | E17: =COUNTIFS('Test Cases'!$B$2:$B$67,$A17,'Test Cases'!$K$2:$K$67,"Blocked") | F17: =COUNTIFS('Test Cases'!$B$2:$B$67,$A17,'Test Cases'!$K$2:$K$67,"N/A") | G17: =COUNTIFS('Test Cases'!$B$2:$B$67,$A17,'Test Cases'!$K$2:$K$67,"Not Run") | H17: =IFERROR(C17/(B17-F17-G17),0)
A18: Final submit — the "Submit Proposal" approval modal | B18: =COUNTIFS('Test Cases'!$B$2:$B$67,$A18) | C18: =COUNTIFS('Test Cases'!$B$2:$B$67,$A18,'Test Cases'!$K$2:$K$67,"Pass") | D18: =COUNTIFS('Test Cases'!$B$2:$B$67,$A18,'Test Cases'!$K$2:$K$67,"Fail") | E18: =COUNTIFS('Test Cases'!$B$2:$B$67,$A18,'Test Cases'!$K$2:$K$67,"Blocked") | F18: =COUNTIFS('Test Cases'!$B$2:$B$67,$A18,'Test Cases'!$K$2:$K$67,"N/A") | G18: =COUNTIFS('Test Cases'!$B$2:$B$67,$A18,'Test Cases'!$K$2:$K$67,"Not Run") | H18: =IFERROR(C18/(B18-F18-G18),0)
A19: After submit and edge cases | B19: =COUNTIFS('Test Cases'!$B$2:$B$67,$A19) | C19: =COUNTIFS('Test Cases'!$B$2:$B$67,$A19,'Test Cases'!$K$2:$K$67,"Pass") | D19: =COUNTIFS('Test Cases'!$B$2:$B$67,$A19,'Test Cases'!$K$2:$K$67,"Fail") | E19: =COUNTIFS('Test Cases'!$B$2:$B$67,$A19,'Test Cases'!$K$2:$K$67,"Blocked") | F19: =COUNTIFS('Test Cases'!$B$2:$B$67,$A19,'Test Cases'!$K$2:$K$67,"N/A") | G19: =COUNTIFS('Test Cases'!$B$2:$B$67,$A19,'Test Cases'!$K$2:$K$67,"Not Run") | H19: =IFERROR(C19/(B19-F19-G19),0)
A20: Total | B20: =SUM(B13:B19) | C20: =SUM(C13:C19) | D20: =SUM(D13:D19) | E20: =SUM(E13:E19) | F20: =SUM(F13:F19) | G20: =SUM(G13:G19) | H20: =IFERROR(C20/(B20-F20-G20),0)
A22: By priority
A23: Priority | B23: Total | C23: Pass | D23: Fail | E23: Blocked | F23: N/A | G23: Not Run | H23: Pass %
A24: P0 | B24: =COUNTIFS('Test Cases'!$E$2:$E$67,$A24) | C24: =COUNTIFS('Test Cases'!$E$2:$E$67,$A24,'Test Cases'!$K$2:$K$67,"Pass") | D24: =COUNTIFS('Test Cases'!$E$2:$E$67,$A24,'Test Cases'!$K$2:$K$67,"Fail") | E24: =COUNTIFS('Test Cases'!$E$2:$E$67,$A24,'Test Cases'!$K$2:$K$67,"Blocked") | F24: =COUNTIFS('Test Cases'!$E$2:$E$67,$A24,'Test Cases'!$K$2:$K$67,"N/A") | G24: =COUNTIFS('Test Cases'!$E$2:$E$67,$A24,'Test Cases'!$K$2:$K$67,"Not Run") | H24: =IFERROR(C24/(B24-F24-G24),0)
A25: P1 | B25: =COUNTIFS('Test Cases'!$E$2:$E$67,$A25) | C25: =COUNTIFS('Test Cases'!$E$2:$E$67,$A25,'Test Cases'!$K$2:$K$67,"Pass") | D25: =COUNTIFS('Test Cases'!$E$2:$E$67,$A25,'Test Cases'!$K$2:$K$67,"Fail") | E25: =COUNTIFS('Test Cases'!$E$2:$E$67,$A25,'Test Cases'!$K$2:$K$67,"Blocked") | F25: =COUNTIFS('Test Cases'!$E$2:$E$67,$A25,'Test Cases'!$K$2:$K$67,"N/A") | G25: =COUNTIFS('Test Cases'!$E$2:$E$67,$A25,'Test Cases'!$K$2:$K$67,"Not Run") | H25: =IFERROR(C25/(B25-F25-G25),0)
A26: P2 | B26: =COUNTIFS('Test Cases'!$E$2:$E$67,$A26) | C26: =COUNTIFS('Test Cases'!$E$2:$E$67,$A26,'Test Cases'!$K$2:$K$67,"Pass") | D26: =COUNTIFS('Test Cases'!$E$2:$E$67,$A26,'Test Cases'!$K$2:$K$67,"Fail") | E26: =COUNTIFS('Test Cases'!$E$2:$E$67,$A26,'Test Cases'!$K$2:$K$67,"Blocked") | F26: =COUNTIFS('Test Cases'!$E$2:$E$67,$A26,'Test Cases'!$K$2:$K$67,"N/A") | G26: =COUNTIFS('Test Cases'!$E$2:$E$67,$A26,'Test Cases'!$K$2:$K$67,"Not Run") | H26: =IFERROR(C26/(B26-F26-G26),0)
A27: P3 | B27: =COUNTIFS('Test Cases'!$E$2:$E$67,$A27) | C27: =COUNTIFS('Test Cases'!$E$2:$E$67,$A27,'Test Cases'!$K$2:$K$67,"Pass") | D27: =COUNTIFS('Test Cases'!$E$2:$E$67,$A27,'Test Cases'!$K$2:$K$67,"Fail") | E27: =COUNTIFS('Test Cases'!$E$2:$E$67,$A27,'Test Cases'!$K$2:$K$67,"Blocked") | F27: =COUNTIFS('Test Cases'!$E$2:$E$67,$A27,'Test Cases'!$K$2:$K$67,"N/A") | G27: =COUNTIFS('Test Cases'!$E$2:$E$67,$A27,'Test Cases'!$K$2:$K$67,"Not Run") | H27: =IFERROR(C27/(B27-F27-G27),0)
A30: Flagged cases | B30: Total | C30: Failed
A31: Suspected bug | B31: =COUNTIFS('Test Cases'!$J$2:$J$67,"Suspected bug") | C31: =COUNTIFS('Test Cases'!$J$2:$J$67,"Suspected bug",'Test Cases'!$K$2:$K$67,"Fail")
A32: Needs product call | B32: =COUNTIFS('Test Cases'!$J$2:$J$67,"Needs product call") | C32: =COUNTIFS('Test Cases'!$J$2:$J$67,"Needs product call",'Test Cases'!$K$2:$K$67,"Fail")
A33: Pass % = Pass ÷ (Total − N/A − Not Run), i.e. of the cases actually executed.

Sheet Test Cases
A1: TC ID | B1: Module | C1: Scenario | D1: Type | E1: Priority | F1: Precondition | G1: Test Steps | H1: Expected Result | I1: Notes | J1: Flag | K1: Status | L1: Actual Result | M1: Bug / Ticket | N1: Tested By | O1: Tested On | P1: Build / Env
A2: NTD-PO-001 | B2: Getting to the PO form | C2: "Create PO" on the awarding screen opens the PO form | D2: Functional | E2: P0 | F2: P-NTD, awarding done, no contract template on the tenant. | G2: 1. Open the project and go to the awarding (QCS) screen. 2. Click Create PO. | H2: The toast "Redirecting you to PO form..." shows, then the PO form opens for this proposal. Each awarded vendor has its own column. The Submit Proposal button is at the top right. | K2: Not Run
A3: NTD-PO-002 | B3: Getting to the PO form | C3: "Proceed ▸ Create PO" works the same when contracts are enabled | D3: Functional | E3: P1 | F3: P-NTD, with a contract template available. | G3: 1. On the awarding screen, click Proceed. 2. Pick Create PO from the menu. | H3: The same PO form opens as in NTD-PO-001. The menu shows Create PO and Create Contract, not Create Proposal. | K3: Not Run
A4: NTD-PO-003 | B4: Getting to the PO form | C4: "Create PO" can't be fired twice | D4: Edge case | E4: P2 | F4: P-NTD. | G4: Double-click Create PO quickly. | H4: The button shows a loader after the first click. Only one PO is created and one redirect happens. No duplicate-PO error. | K4: Not Run
A5: NTD-PO-004 | B5: Getting to the PO form | C5: The Proposed PO Form tab appears on the proposal page | D5: Functional | E5: P2 | F5: P-NTD, PO created. | G5: Open the proposal page and look at the stage tabs. | H5: A Proposed PO Form tab is listed and opens the same PO form. In P-NTD-SKIP (skip_custom_po = true) this tab isn't shown. | K5: Not Run
A6: NTD-PO-005 | B6: The PO form — fields and validation | C6: Every PO field saves on its own and survives a reload | D6: Regression | E6: P0 | F6: PO form open (P-NTD). | G6: 1. For one vendor, fill one field of each type: text, number, date, dropdown. 2. Reload the page. | H6: Each field saves as soon as you leave it (a save call fires per field). After the reload, every value is still there, in the right vendor's column. | K6: Not Run
A7: NTD-PO-006 | B7: The PO form — fields and validation | C7: Required PO fields are marked | D7: Regression | E7: P1 | F7: PO form open for a P-NTD proposal, with at least one vendor column visible. | G7: Look at the PO form for one vendor. | H7: Mandatory fields are visibly marked as required. Read-only or system fields, such as vendor name and totals, can't be edited. | K7: Not Run
A8: NTD-PO-007 | B8: The PO form — fields and validation | C8: Text field limits | D8: Regression | E8: P2 | F8: PO form open for a P-NTD proposal, with at least one vendor column visible. | G8: In a PO text field, try: • an empty value • only spaces • a 255-character string • a 1,000-character string • special characters and HTML: <b>Test</b> & "quotes" ‘smart’ ₹ 😀 | H8: Spaces alone don't count as filled for a required field. Long text is either accepted or cut at the configured limit with a message; it never fails silently. HTML is shown as plain text, never rendered. Unicode and ₹ are saved and shown correctly. | K8: Not Run
A9: NTD-PO-008 | B9: The PO form — fields and validation | C9: Number and amount fields | D9: Regression | E9: P1 | F9: PO form open for a P-NTD proposal, with at least one vendor column visible. | G9: In a PO number or amount field, try 0, -5, 1.555, abc, 1e5, a 15-digit number, and pasting 1,00,000. | H9: • Letters can't be typed in. • Negative values follow the field config (rejected if the field disallows them). • Decimals are rounded or limited to the configured precision. • Large values don't turn into scientific notation. • The pasted Indian-format number is either parsed correctly or rejected with a clear message. | K9: Not Run
A10: NTD-PO-009 | B10: The PO form — fields and validation | C10: Date fields | D10: Regression | E10: P1 | F10: PO form open for a P-NTD proposal, with at least one vendor column visible. | G10: Open a PO date picker. Pick a past date, today, and a future date. Type an invalid date by hand. Clear the field. | H10: Any min/max rule is enforced, for example "delivery date can't be in the past". An invalid date typed by hand isn't saved. Clearing a required date leaves it empty and marked required. | K10: Not Run
A11: NTD-PO-010 | B11: The PO form — fields and validation | C11: Dropdown fields | D11: Regression | E11: P2 | F11: PO form open for a P-NTD proposal, with at least one vendor column visible. | G11: Open a PO dropdown. Search within it, pick a value, change it, then clear it. | H11: Search filters the options. Each change saves. Clearing a required dropdown leaves it marked required. | K11: Not Run
A12: NTD-PO-011 | B12: The PO form — fields and validation | C12: Quick Fill copies values into the vendor column | D12: Regression | E12: P2 | F12: PO form open for a P-NTD proposal, with at least one vendor column visible. | G12: Open Quick Fill for one vendor. Fill in values and apply. | H12: The values land in that vendor's column only and are saved. Other vendors' columns aren't touched. | K12: Not Run
A13: NTD-PO-012 | B13: The PO form — fields and validation | C13: PO prefill from the last PO (if the tenant has it) | D13: Regression | E13: P2 | F13: PO prefill on for the tenant. The vendor already has an older PO. | G13: Open the PO form and scroll so the vendor's column comes into view. | H13: Fields are prefilled from the vendor's last PO. The prefill is saved once and survives a reload. Prefilled values can still be edited. | K13: Not Run
... A19: NTD-PO-018 | B19: "Submit Proposal" on the PO form — the core change | C19: A clear error if the project reference is missing | D19: Negative | E19: P1 | F19: P-NTD. Simulate a missing item_uuid, for example by blocking the proposal-details call in DevTools or opening the PO form in a state where the proposal details didn't load. | G19: Click Submit Proposal. | H19: The error toast "Could not open the NTD form. Please refresh and retry." shows. The page stays on the PO form, with no blank page and no half-open modal. After a refresh, Submit works. | K19: Not Run
A20: NTD-PO-019 | B20: "Submit Proposal" on the PO form — the core change | C20: What happens to a PO with empty mandatory fields | D20: Negative | E20: P0 | F20: P-NTD. Leave one or more mandatory PO fields empty. | G20: Click Submit Proposal on the PO form. | H20: (To confirm) Either the PO form blocks the handoff and highlights the empty fields, or the final submit is blocked by the backend with a message that names the PO form. It must not be possible to submit the proposal with an incomplete PO. | I20: The PR redirects straight away without checking PO fields, so today this probably goes through to the NTD form. Log it as a bug if the final submit also succeeds. | J20: Suspected bug | K20: Not Run
A21: NTD-PO-020 | B21: "Submit Proposal" on the PO form — the core change | C21: Clicking Submit Proposal twice | D21: Edge case | E21: P3 | F21: P-NTD. PO form open and filled in. | G21: Double-click Submit Proposal on the PO form. | H21: One navigation to the NTD form. Browser Back takes you back to the PO form once, not to a second copy of the NTD page. | K21: Not Run
A22: NTD-PO-021 | B22: "Submit Proposal" on the PO form — the core change | C22: Browser Back from the NTD form | D22: Edge case | E22: P1 | F22: P-NTD. PO form filled in. | G22: 1. Go from the PO form to the NTD form. 2. Press browser Back. | H22: The PO form opens again with every value intact and still editable. Clicking Submit Proposal again brings you back to the NTD form, and any NTD values you already entered are still there. | K22: Not Run
A23: NTD-PO-022 | B23: "Submit Proposal" on the PO form — the core change | C23: Unsaved PO edit at the moment of Submit | D23: Edge case | E23: P2 | F23: P-NTD. PO form open. | G23: Type into a PO field and, without clicking away, click Submit Proposal straight away. | H23: The last edit is still saved: when you go back to the PO form, the value is there. If it isn't, log it as a bug. The navigation shouldn't drop the pending save. | K23: Not Run
A24: NTD-PO-023 | B24: "Submit Proposal" on the PO form — the core change | C24: The lot number is kept on the handoff (lot-based events) | D24: Functional | E24: P0 | F24: P-NTD-LOT. Open the PO form for Lot 2. | G24: 1. Click Submit Proposal. 2. Check the URL, the page title ("- Lot 2"), the approval sidebar, and the report download on the NTD page. | H24: Everything shows Lot 2. The approval sidebar lists Lot 2's approvals, not all lots or none. A report downloads for Lot 2. | I24: The redirect URL has no ?lotNo=. The title will probably be right, because it comes from the proposal data, but the sidebar and reports read lotNo from the URL. Check these carefully. | J24: Suspected bug | K24: Not Run
A25: NTD-PO-024 | B25: "Submit Proposal" on the PO form — the core change | C25: The reorder flow with NTD on | D25: Edge case | E25: P1 | F25: A reorder with ?source=reorder on the PO form URL, on a project where NTD is on. | G25: Click Submit Proposal. | H25: (To confirm) The code sends the user to the NTD form before it checks for the reorder flow, so the reorder approval modal no longer shows. Product should confirm this is intended. If it isn't, the reorder modal should open as before. | J25: Needs product call | K25: Not Run
A26: NTD-PO-025 | B26: "Submit Proposal" on the PO form — the core change | C26: Reorder without NTD is unchanged | D26: Regression | E26: P1 | F26: Reorder on a project with NTD off. | G26: Click Submit Proposal. | H26: The Select Approval Flow reorder modal opens. Submit without choosing a flow shows "Please select an approval flow". Picking a flow and submitting takes you to Reorder Approvals. | K26: Not Run
A27: NTD-PO-026 | B27: The NTD (entity) form | C27: The NTD form loads in draft with a default template | D27: Functional | E27: P0 | F27: Arrived from the PO form (NTD-PO-015). | G27: Look at the Document panel. | H27: • The Proposal Template dropdown is shown. It holds the first saved template, or the one already chosen for this proposal. • The template's sections and fields show and can be edited. • The Submit Proposal button is shown at the top right. | K27: Not Run
A28: NTD-PO-027 | B28: The NTD (entity) form | C28: Switching the template | D28: Functional | E28: P1 | F28: P-NTD. On the NTD form, reached by clicking Submit Proposal on the PO form (NTD-PO-015). | G28: Change Proposal Template to another saved template. | H28: The sections switch to the new template's fields. Values typed into the old template aren't carried into the wrong fields. | K28: Not Run
A29: NTD-PO-028 | B29: The NTD (entity) form | C29: Each section saves on its own | D29: Functional | E29: P0 | F29: P-NTD. On the NTD form, reached by clicking Submit Proposal on the PO form (NTD-PO-015). | G29: Fill a field in section 1, then a field in section 2. Reload. | H29: A save fires for the section you changed only. After the reload, both values are still there. | K29: Not Run
A30: NTD-PO-029 | B30: The NTD (entity) form | C30: Submitting an empty NTD form is blocked | D30: Negative | E30: P0 | F30: P-NTD. On the NTD form, reached by clicking Submit Proposal on the PO form (NTD-PO-015). | G30: Leave every required field empty and click Submit Proposal. | H30: • The toast "Please fill all the required fields" shows. • Each section with a missing field shows its error ("Please fill all required fields"). • The approval modal does not open. | K30: Not Run
A31: NTD-PO-030 | B31: The NTD (entity) form | C31: Required text field | D31: Negative | E31: P1 | F31: P-NTD. On the NTD form, reached by clicking Submit Proposal on the PO form (NTD-PO-015). | G31: Fill every required field except one text field, then submit. Next, fill it with spaces only and submit. Finally, fill it with real text and submit. | H31: An empty field blocks submit, and the error shows on that field's section. Real text lets you through. For spaces only, check whether they're treated as filled and log what you see. They ideally shouldn't count. | K31: Not Run
A32: NTD-PO-031 | B32: The NTD (entity) form | C32: Optional fields don't block submit | D32: Functional | E32: P0 | F32: P-NTD. On the NTD form, reached by clicking Submit Proposal on the PO form (NTD-PO-015). | G32: Fill only the required fields and leave the optional ones empty. Submit. | H32: No error. The approval modal opens. | K32: Not Run
A33: NTD-PO-032 | B33: The NTD (entity) form | C33: A price or amount of 0 counts as filled | D33: Functional | E33: P1 | F33: P-NTD. On the NTD form, reached by clicking Submit Proposal on the PO form (NTD-PO-015). | G33: Put 0 in a required price or amount field. Submit. | H33: It's accepted and doesn't count as empty. | K33: Not Run
A34: NTD-PO-033 | B34: The NTD (entity) form | C34: Required number field (not price) | D34: Negative | E34: P2 | F34: P-NTD. On the NTD form, reached by clicking Submit Proposal on the PO form (NTD-PO-015). | G34: Put 0 in a required plain number field. Submit. Then clear it and submit again. | H34: A cleared field must block submit. For 0, write down what happens. In this code, only price and amount fields are exempt from the "0 is empty" check, so a plain number field may reject 0 (it depends on whether the value is stored as the number 0 or the text "0"). Confirm with product which is intended. | J34: Needs product call | K34: Not Run
A35: NTD-PO-034 | B35: The NTD (entity) form | C35: Required dropdown, date and attachment fields | D35: Negative | E35: P1 | F35: P-NTD. On the NTD form, reached by clicking Submit Proposal on the PO form (NTD-PO-015). | G35: For each type, leave it empty and submit, then fill it and submit again. | H35: Empty blocks submit with the section error. Filled lets you through. For an attachment, an upload that failed or is still running doesn't count as filled. | K35: Not Run
A36: NTD-PO-035 | B36: The NTD (entity) form | C36: Grouped table: a partly filled row is caught | D36: Negative | E36: P1 | F36: The template has a grouped-table section with required columns. | G36: Add a row and fill only some of the required columns. Submit. | H36: The section shows "Sheet partially filled". Submit is blocked. | K36: Not Run
A37: NTD-PO-036 | B37: The NTD (entity) form | C37: Grouped table: a cleared required number cell | D37: Negative | E37: P1 | F37: P-NTD template with a grouped-table section that has a required number or quantity column. On the NTD form. | G37: In a grouped-table row, type a number into a required number or quantity column, then delete it so the cell is empty. Submit. | H37: Submit should be blocked with "Sheet partially filled". | I37: In the code, Number("") is 0, which counts as valid. The empty cell will probably pass. Log it as a bug if it does. | J37: Suspected bug | K37: Not Run
A38: NTD-PO-037 | B38: The NTD (entity) form | C38: Grouped table: the blank last row is ignored | D38: Functional | E38: P1 | F38: P-NTD template with a grouped-table section. On the NTD form. | G38: Fill the required columns in all rows. Leave the trailing empty "new row" at the bottom as it is. Submit. | H38: No error. The empty last row isn't validated. | K38: Not Run
A39: NTD-PO-038 | B39: The NTD (entity) form | C39: Read-only fields are never required | D39: Functional | E39: P2 | F39: The template has a field marked both required and read-only. On the NTD form. | G39: The template has a field that is both required and read-only. Submit without touching it. | H39: It doesn't block submit. | K39: Not Run
A40: NTD-PO-039 | B40: The NTD (entity) form | C40: BOQ section validation (if the template has one) | D40: Negative | E40: P2 | F40: The template has a BOQ section. On the NTD form. | G40: 1. Submit with no BOQ template picked. 2. Submit with a template but no data. 3. Submit with more line items than the limit. | H40: The error messages are, in order: "Please select a BOQ template", "Please upload correct BOQ data", and "You can have at max N line-items…". | K40: Not Run
A41: NTD-PO-040 | B41: The NTD (entity) form | C41: Errors clear once fixed | D41: Functional | E41: P1 | F41: P-NTD. On the NTD form, reached by clicking Submit Proposal on the PO form (NTD-PO-015). | G41: Trigger section errors (NTD-PO-029), fill the fields, and submit again. | H41: The errors go away. The approval modal opens. | K41: Not Run
A42: NTD-PO-041 | B42: The NTD (entity) form | C42: Field-level input limits on the NTD form | D42: Negative | E42: P2 | F42: P-NTD. On the NTD form, reached by clicking Submit Proposal on the PO form (NTD-PO-015). | G42: Repeat the input checks from NTD-PO-007 to NTD-PO-010 (long text, special characters, emoji, letters in number fields, decimals, invalid dates) on the NTD fields. | H42: Same rules as on the PO form. HTML is never rendered. Values save and reload correctly. | K42: Not Run
A43: NTD-PO-042 | B43: "Submit Proposal" on the NTD form — the core change | C43: A valid NTD opens the approval modal and doesn't go back to the PO form | D43: Functional | E43: P0 | F43: P-NTD. PO form filled, arrived at the NTD form, all required NTD fields filled. | G43: Click Submit Proposal. | H43: • The Submit Proposal approval modal opens on the proposal page, with a loader while approval flows load. • The toast "Redirecting you to PO form..." does not show. • No new PO is created, and the page doesn't go to the PO form. | K43: Not Run
A44: NTD-PO-043 | B44: "Submit Proposal" on the NTD form — the core change | C44: Same behaviour when skip_custom_po is on | D44: Regression | E44: P1 | F44: P-NTD-SKIP. From awarding, click Create Proposal; there's no PO form in this path. | G44: Fill the NTD form and click Submit Proposal. | H44: The approval modal opens, the same as before the PR. | K44: Not Run
A45: NTD-PO-044 | B45: "Submit Proposal" on the NTD form — the core change | C45: Opening the NTD page directly without going through the PO form | D45: Negative | E45: P0 | F45: P-NTD, skip_custom_po = false. The proposal has no PO filled. Open the proposal URL directly, or through the version dropdown. | G45: Fill the NTD form and submit until the final approval submit. | H45: (To confirm) The proposal shouldn't be submitted without a PO. Either the page points the user to the PO form, or the backend rejects the submit with a clear message. | I45: The PR removed the step that used to send users to the PO form from here, so this path now leads straight to approval. | J45: Suspected bug | K45: Not Run
...

Sheet Flow & Setup
A1: What the PR changes
B3: Before this PR | C3: After this PR
A4: Order (NTD on) | B4: Proposal page (NTD) → Submit → PO form → Submit → approval | C4: Awarding → PO form → Submit Proposal → NTD (entity) form → Submit Proposal → approval (final submit)
A5: PO form "Submit Proposal" | B5: Always opened the approval modal | C5: NTD on: goes to the proposal page (NTD form). NTD off: opens the approval modal, same as before.
A6: NTD form "Submit Proposal" | B6: With skip_custom_po off, created the PO and redirected to the PO form | C6: Always validates the NTD form, then opens the approval modal. No longer sends you back to the PO form.
A7: Where the NTD flag is read | B7: — | C7: PO form: custom PO schema config.ntd_required_on_proposal. Proposal page: project config.ntd_required_on_proposal (and skip_custom_po).
A10: Test data and setup
A12: Name | B12: Setup
A13: P-NTD | B13: eRFX project, awarding done for at least 2 vendors. ntd_required_on_proposal = true, skip_custom_po = false. At least one NTD proposal template saved with a mix of required and optional fields: text, number, price/amount, dropdown, date, attachment, one grouped-table section and, if the tenant has it, a BOQ section.
A14: P-NTD-LOT | B14: Same as P-NTD, but lot-based awarding (Lot 1, Lot 2).
A15: P-NO-NTD | B15: Same as P-NTD, but ntd_required_on_proposal = false.
A16: P-NTD-SKIP | B16: ntd_required_on_proposal = true, skip_custom_po = true.
A17: Approval flows | B17: Three variants on the tenant: none, exactly one, and more than one. At least one flow with a step that has approver_select on, so the user has to pick the approver.
A18: Users | B18: Buyer who owns the proposal and has awarding rights. A second buyer without edit rights on the project, for the negative cases.
A20: "Entity form" = the NTD form: the Document panel on the proposal page, with the Proposal Template dropdown and the template's sections.

Sheet Open Questions
A1: # | B1: Question / suspected issue | C1: Related TC | D1: Owner | E1: Status | F1: Response
A2: 1 | B2: The PO → NTD redirect URL has no ?lotNo=. On a lot-based event the proposal page gets an empty lotNo and passes it on to the approval sidebar and the report download. | C2: NTD-PO-023 | D2: Dev | E2: Open
A3: 2 | B3: "Submit Proposal" on the PO form redirects without checking PO fields, so a PO with empty mandatory fields can reach the NTD form. Is the final submit blocked by the backend? | C3: NTD-PO-019 | D3: Dev | E3: Open
A4: 3 | B4: The step that sent users from the NTD page to the PO form was removed. Opening the NTD page directly (URL / version dropdown) with no PO filled now leads straight to approval. | C4: NTD-PO-044 | D4: Dev / Product | E4: Open
A5: 4 | B5: In grouped-table sections the check uses Number(value); Number("") is 0, so a cleared required number/quantity cell counts as filled. | C5: NTD-PO-036 | D5: Dev | E5: Open
A6: 5 | B6: The approval modal closes even when submission fails, so remarks and attachments are lost. Acceptable? | C6: NTD-PO-058 | D6: Product | E6: Open
A7: 6 | B7: The X on the approval modal resets it to the flow list, the Cancel button does not. Should both behave the same? | C7: NTD-PO-056 | D7: Product | E7: Open
A8: 7 | B8: With NTD on, a reorder (?source=reorder) now goes to the NTD form instead of the reorder approval modal. Intended? | C8: NTD-PO-024 | D8: Product | E8: Open
A9: 8 | B9: NTD on/off is read from two places (PO schema config vs project config). What should happen if they disagree? | C9: NTD-PO-064 | D9: Dev | E9: Open
A10: 9 | B10: Should 0 be accepted in a required plain number field on the NTD form? Only price/amount fields are exempt today. | C10: NTD-PO-033 | D10: Product | E10: Open
